wandb: WARNING Calling wandb.login() after wandb.init() has no effect.
Traceback (most recent call last):
  File "r_exp.py", line 514, in <module>
    main('aifb',node_idx= 5791, prune= True, explain_all =True, train=True)
  File "r_exp.py", line 420, in main
    masked_hor, masked_ver = explainer.explain(node_idx)
  File "r_exp.py", line 138, in explain
    loss = explainer.loss(ypred, pred_label, self.node_idx, epoch)  # loss function
  File "r_exp.py", line 313, in loss
    if len(num_high)>300:
TypeError: object of type 'int' has no len()
masked_adj tensor([0.7773, 0.7672, 0.7534, 0.6742, 0.7480, 0.6985, 0.7300, 0.6883, 0.7115,
        0.7710, 0.7209, 0.6938, 0.7121, 0.7166, 0.7110, 0.7500, 0.7708, 0.7270,
        0.7182, 0.7421, 0.7113, 0.7576, 0.7510, 0.7717, 0.7624, 0.7628, 0.7463,
        0.7637, 0.7251, 0.7321, 0.7246, 0.7524, 0.6943, 0.7083, 0.7253, 0.7725,
        0.7391, 0.7201, 0.7388, 0.7109, 0.6896, 0.7557, 0.7081, 0.7155, 0.6974,
        0.7816, 0.6985, 0.7184, 0.7071, 0.7140, 0.7330, 0.7442, 0.7184, 0.7603,
        0.7098, 0.7119, 0.6938, 0.7320, 0.7294, 0.7479, 0.7286, 0.7754, 0.6998,
        0.7648, 0.7663, 0.7523, 0.7837, 0.7442, 0.7398, 0.7260, 0.7033, 0.7624,
        0.7266, 0.7442, 0.7325, 0.7418, 0.7455, 0.7144, 0.6713, 0.7115, 0.7313,
        0.7223, 0.6955, 0.7159, 0.7445, 0.7442, 0.7591, 0.7324, 0.7496, 0.7186,
        0.7035, 0.7462, 0.6850, 0.7094, 0.7637, 0.7432, 0.6625, 0.7433, 0.7506,
        0.7318, 0.7471, 0.7457, 0.7574, 0.7443, 0.7565, 0.7127, 0.7561, 0.7225,
        0.7440, 0.7408, 0.7160, 0.7414, 0.7162, 0.7438, 0.7188, 0.7183, 0.7379,
        0.7165, 0.7480], grad_fn=<MulBackward0>)
res: tensor([9.9855e-01, 6.6735e-04, 9.8767e-05, 6.8133e-04],
       grad_fn=<SoftmaxBackward0>)