2023-06-12 09:14:01 WARNING Retrying (Retry(total=2, connect=None, read=None, redirect=None, status=None)) after connection broken by 'NewConnectionError('<urllib3.connection.HTTPSConnection object at 0x7fbeb91321c0>: Failed to establish a new connection: [Errno 8] nodename nor servname provided, or not known')': /api/4504800232407040/envelope/
2023-06-12 09:14:01 WARNING Retrying (Retry(total=1, connect=None, read=None, redirect=None, status=None)) after connection broken by 'NewConnectionError('<urllib3.connection.HTTPSConnection object at 0x7fbeb9132c40>: Failed to establish a new connection: [Errno 8] nodename nor servname provided, or not known')': /api/4504800232407040/envelope/
2023-06-12 09:14:01 WARNING Retrying (Retry(total=0, connect=None, read=None, redirect=None, status=None)) after connection broken by 'NewConnectionError('<urllib3.connection.HTTPSConnection object at 0x7fbeb9132700>: Failed to establish a new connection: [Errno 8] nodename nor servname provided, or not known')': /api/4504800232407040/envelope/
2023-06-13 12:56:57 ERROR 400 response executing GraphQL.
2023-06-13 12:56:57 ERROR {"errors":[{"message":"entityName required for models query","path":["models"]}],"data":{"models":null}}
2023-06-13 12:56:57 ERROR Traceback (most recent call last):
  File "/usr/local/Caskroom/miniconda/base/lib/python3.9/site-packages/wandb/apis/normalize.py", line 41, in wrapper
    return func(*args, **kwargs)
  File "/usr/local/Caskroom/miniconda/base/lib/python3.9/site-packages/wandb/sdk/internal/internal_api.py", line 733, in list_projects
    self.gql(
  File "/usr/local/Caskroom/miniconda/base/lib/python3.9/site-packages/wandb/sdk/internal/internal_api.py", line 292, in gql
    ret = self._retry_gql(
  File "/usr/local/Caskroom/miniconda/base/lib/python3.9/site-packages/wandb/sdk/lib/retry.py", line 131, in __call__
    result = self._call_fn(*args, **kwargs)
  File "/usr/local/Caskroom/miniconda/base/lib/python3.9/site-packages/wandb/sdk/internal/internal_api.py", line 320, in execute
    return self.client.execute(*args, **kwargs)  # type: ignore
  File "/usr/local/Caskroom/miniconda/base/lib/python3.9/site-packages/wandb/vendor/gql-0.2.0/wandb_gql/client.py", line 52, in execute
    result = self._get_result(document, *args, **kwargs)
  File "/usr/local/Caskroom/miniconda/base/lib/python3.9/site-packages/wandb/vendor/gql-0.2.0/wandb_gql/client.py", line 60, in _get_result
    return self.transport.execute(document, *args, **kwargs)
  File "/usr/local/Caskroom/miniconda/base/lib/python3.9/site-packages/wandb/sdk/lib/gql_request.py", line 56, in execute
    request.raise_for_status()
  File "/usr/local/Caskroom/miniconda/base/lib/python3.9/site-packages/requests/models.py", line 1021, in raise_for_status
    raise HTTPError(http_error_msg, response=self)
requests.exceptions.HTTPError: 400 Client Error: Bad Request for url: https://api.wandb.ai/graphql

During handling of the above exception, another exception occurred:

Traceback (most recent call last):
  File "/usr/local/Caskroom/miniconda/base/lib/python3.9/site-packages/wandb/cli/cli.py", line 106, in wrapper
    return func(*args, **kwargs)
  File "/usr/local/Caskroom/miniconda/base/lib/python3.9/site-packages/wandb/cli/cli.py", line 197, in projects
    projects = api.list_projects(entity=entity)
  File "/usr/local/Caskroom/miniconda/base/lib/python3.9/site-packages/wandb/apis/internal.py", line 84, in list_projects
    return self.api.list_projects(entity=entity)
  File "/usr/local/Caskroom/miniconda/base/lib/python3.9/site-packages/wandb/apis/normalize.py", line 51, in wrapper
    raise CommError(message, error)
wandb.errors.CommError: entityName required for models query (Error 400: Bad Request)

